Workbook
Name OLE_LINK1: DISs!#REF!

Sheet Figure 1
A3: country | B3: Count of country
A4: Japan | B4: 1
A5: Estonia | B5: 1
A6: Sweden | B6: 1
A7: Germany | B7: 1
A8: Denmark | B8: 1
A9: Spain | B9: 1
A10: Australia | B10: 2
A11: Slovenia | B11: 2
A12: Belgium | B12: 2
A13: Italy | B13: 2
A14: Switzerland | B14: 3
A15: France | B15: 5
... A18: Netherlands | B18: 19

Sheet Figure 2
A1: Feature | B1: n | C1: % | D1: n PIMS | E1: % PIMS | F1: n infra | G1: % infra | H1: n coop | I1: % coop | J1: n mono | K1: % | L1: n multi | M1: % | N1: n personal | O1: n npersonal
A2: Data access mention | B2: =SUM(DISs!$B$2:$B$98) -> 13 | C2: =B2/$B$7 -> 0.24074074 | D2: =SUMIF(DISs!$L$2:$L$495,"subject",DISs!$B$2:$B$495) -> 9 | E2: =D2/$B$17 -> 0.25714286 | F2: =SUMIF(DISs!$L$2:$L$495,"enabler",DISs!$B$2:$B$495) -> 4 | G2: =F2/$B$18 -> 0.21052632 | H2: =SUMIF(DISs!$L$2:$L$495,"cooperative",DISs!$B$2:$B$495) -> 0 | I2: =H2*100/$B$19 -> #DIV/0! | J2: =SUMIF(DISs!$N$2:$N$495,"mono",DISs!$B$2:$B$495) -> 7 | K2: =J2/B13 -> 0.38888889 | L2: =SUMIF(DISs!$N$2:$N$495,"multi",DISs!$B$2:$B$495) -> 6 | M2: =L2/B14 -> 0.16666667 | N2: =SUMIF(DISs!$O$2:$O$495,"personal",DISs!$B$2:$B$495) -> 5 | O2: =SUMIF(DISs!$O$2:$O$495,"non-personal",DISs!$B$2:$B$495) -> 3
A3: Dedicated data access | B3: =SUM(DISs!$C$2:$C$98) -> 5 | C3: =B3/$B$7 -> 0.092592593 | D3: =SUMIF(DISs!$L$2:$L$495,"subject",DISs!$C$2:$C$495) -> 4 | E3: =D3/$B$17 -> 0.11428571 | F3: =SUMIF(DISs!$L$2:$L$495,"enabler",DISs!$C$2:$C$495) -> 1 | G3: =F3/$B$18 -> 0.052631579 | H3: =SUMIF(DISs!$L$2:$L$495,"cooperative",DISs!$C$2:$C$495) -> 0 | I3: =H3*100/$B$19 -> #DIV/0! | J3: =SUMIF(DISs!$N$2:$N$495,"mono",DISs!$C$2:$C$495) -> 5 | K3: =J3/B13 -> 0.27777778 | L3: =SUMIF(DISs!$N$2:$N$495,"multi",DISs!$C$2:$C$495) -> 0 | M3: =L3/B14 -> 0 | N3: =SUMIF(DISs!$O$2:$O$495,"personal",DISs!$C$2:$C$495) -> 4 | O3: =SUMIF(DISs!$O$2:$O$495,"non-personal",DISs!$C$2:$C$495) -> 1
A4: Documented implementation in research project | B4: =SUM(DISs!$D$2:$D$98) -> 12 | C4: =B4/$B$7 -> 0.22222222 | D4: =SUMIF(DISs!$L$2:$L$495,"subject",DISs!$D$2:$D$495) -> 10 | E4: =D4/$B$17 -> 0.28571429 | F4: =SUMIF(DISs!$L$2:$L$495,"enabler",DISs!$D$2:$D$495) -> 2 | G4: =F4/$B$18 -> 0.10526316 | H4: =SUMIF(DISs!$L$2:$L$495,"cooperative",DISs!$D$2:$D$495) -> 0 | I4: =H4*100/$B$19 -> #DIV/0! | J4: =SUMIF(DISs!$N$2:$N$495,"mono",DISs!$D$2:$D$495) -> 7 | K4: =J4/B13 -> 0.38888889 | L4: =SUMIF(DISs!$N$2:$N$495,"multi",DISs!$D$2:$D$495) -> 5 | M4: =L4/B14 -> 0.13888889 | N4: =SUMIF(DISs!$O$2:$O$495,"personal",DISs!$D$2:$D$495) -> 6 | O4: =SUMIF(DISs!$O$2:$O$495,"non-personal",DISs!$D$2:$D$495) -> 2
A7: tot | B7: 54
A13: unspecialised | B13: =COUNTIF(DISs!$N$2:$N$495,"mono") -> 18
A14: specialised | B14: =COUNTIF(DISs!$N$2:$N$495,"multi") -> 36
A15: tot agriculture | B15: =COUNTIF(DISs!$N$2:$N$495,"agriculture") -> 0
A16: order: State - NGO - Firm
A17: subject-centred | B17: =COUNTIF(DISs!$L$2:$L$495,"subject") -> 35
A18: infrastructure | B18: =COUNTIF(DISs!$L$2:$L$495,"enabler") -> 19
A19: cooperative | B19: =COUNTIF(DISs!$L$2:$L$495,"cooperative") -> 0
A26: n features | B26: frequency
A27: 0 | B27: =COUNTIF(DISs!$E$2:$E$495,A27) -> 38 | C27: 0 features
A28: 1 | B28: =COUNTIF(DISs!$E$2:$E$495,A28) -> 7 | C28: 1 features
A29: 2 | B29: =COUNTIF(DISs!$E$2:$E$495,A29) -> 4 | C29: 2 features
A30: 3 | B30: =COUNTIF(DISs!$E$2:$E$495,A30) -> 5 | C30: 3 features
A31: 4 | B31: =COUNTIF(DISs!$E$2:$E$495,A31) -> 0 | C31: 4 features
A32: 5 | B32: =COUNTIF(DISs!$E$2:$E$495,A32) -> 0 | C32: 5 features

Sheet Figure 3
A1: Feature | B1: n | C1: % | D1: n PIMS | E1: % PIMS | F1: n infra | G1: % infra | H1: n coop | I1: % coop | J1: n mono | K1: % | L1: n multi | M1: % | N1: n personal | O1: n npersonal
A2: Data access mention | B2: =SUM(DISs!$B$2:$B$98) -> 13 | C2: =B2/$B$7 -> 0.24074074 | D2: =SUMIF(DISs!$L$2:$L$495,"subject",DISs!$B$2:$B$495) -> 9 | E2: =D2/$B$17 -> 0.25714286 | F2: =SUMIF(DISs!$L$2:$L$495,"enabler",DISs!$B$2:$B$495) -> 4 | G2: =F2/$B$18 -> 0.21052632 | H2: =SUMIF(DISs!$L$2:$L$495,"cooperative",DISs!$B$2:$B$495) -> 0 | I2: =H2*100/$B$19 -> #DIV/0! | J2: =SUMIF(DISs!$N$2:$N$495,"mono",DISs!$B$2:$B$495) -> 7 | K2: =J2/B13 -> 0.38888889 | L2: =SUMIF(DISs!$N$2:$N$495,"multi",DISs!$B$2:$B$495) -> 6 | M2: =L2/B14 -> 0.16666667 | N2: =SUMIF(DISs!$O$2:$O$495,"personal",DISs!$B$2:$B$495) -> 5 | O2: =SUMIF(DISs!$O$2:$O$495,"non-personal",DISs!$B$2:$B$495) -> 3
A3: Dedicated data access | B3: =SUM(DISs!$C$2:$C$98) -> 5 | C3: =B3/$B$7 -> 0.092592593 | D3: =SUMIF(DISs!$L$2:$L$495,"subject",DISs!$C$2:$C$495) -> 4 | E3: =D3/$B$17 -> 0.11428571 | F3: =SUMIF(DISs!$L$2:$L$495,"enabler",DISs!$C$2:$C$495) -> 1 | G3: =F3/$B$18 -> 0.052631579 | H3: =SUMIF(DISs!$L$2:$L$495,"cooperative",DISs!$C$2:$C$495) -> 0 | I3: =H3*100/$B$19 -> #DIV/0! | J3: =SUMIF(DISs!$N$2:$N$495,"mono",DISs!$C$2:$C$495) -> 5 | K3: =J3/B13 -> 0.27777778 | L3: =SUMIF(DISs!$N$2:$N$495,"multi",DISs!$C$2:$C$495) -> 0 | M3: =L3/B14 -> 0 | N3: =SUMIF(DISs!$O$2:$O$495,"personal",DISs!$C$2:$C$495) -> 4 | O3: =SUMIF(DISs!$O$2:$O$495,"non-personal",DISs!$C$2:$C$495) -> 1
A4: Documented implementation in research project | B4: =SUM(DISs!$D$2:$D$98) -> 12 | C4: =B4/$B$7 -> 0.22222222 | D4: =SUMIF(DISs!$L$2:$L$495,"subject",DISs!$D$2:$D$495) -> 10 | E4: =D4/$B$17 -> 0.28571429 | F4: =SUMIF(DISs!$L$2:$L$495,"enabler",DISs!$D$2:$D$495) -> 2 | G4: =F4/$B$18 -> 0.10526316 | H4: =SUMIF(DISs!$L$2:$L$495,"cooperative",DISs!$D$2:$D$495) -> 0 | I4: =H4*100/$B$19 -> #DIV/0! | J4: =SUMIF(DISs!$N$2:$N$495,"mono",DISs!$D$2:$D$495) -> 7 | K4: =J4/B13 -> 0.38888889 | L4: =SUMIF(DISs!$N$2:$N$495,"multi",DISs!$D$2:$D$495) -> 5 | M4: =L4/B14 -> 0.13888889 | N4: =SUMIF(DISs!$O$2:$O$495,"personal",DISs!$D$2:$D$495) -> 6 | O4: =SUMIF(DISs!$O$2:$O$495,"non-personal",DISs!$D$2:$D$495) -> 2
A7: tot | B7: 54
A13: unspecialised | B13: =COUNTIF(DISs!$N$2:$N$495,"mono") -> 18
A14: specialised | B14: =COUNTIF(DISs!$N$2:$N$495,"multi") -> 36
A15: tot agriculture | B15: =COUNTIF(DISs!$N$2:$N$495,"agriculture") -> 0
A16: order: State - NGO - Firm
A17: subject-centred | B17: =COUNTIF(DISs!$L$2:$L$495,"subject") -> 35
A18: infrastructure | B18: =COUNTIF(DISs!$L$2:$L$495,"enabler") -> 19
A19: cooperative | B19: =COUNTIF(DISs!$L$2:$L$495,"cooperative") -> 0
A26: n features | B26: frequency
A27: 0 | B27: =COUNTIF(DISs!$E$2:$E$495,A27) -> 38 | C27: 0 features
A28: 1 | B28: =COUNTIF(DISs!$E$2:$E$495,A28) -> 7 | C28: 1 features
A29: 2 | B29: =COUNTIF(DISs!$E$2:$E$495,A29) -> 4 | C29: 2 features
A30: 3 | B30: =COUNTIF(DISs!$E$2:$E$495,A30) -> 5 | C30: 3 features
A31: 4 | B31: =COUNTIF(DISs!$E$2:$E$495,A31) -> 0 | C31: 4 features
A32: 5 | B32: =COUNTIF(DISs!$E$2:$E$495,A32) -> 0 | C32: 5 features

Sheet Figure 4
A1: Feature | B1: n | C1: % | D1: n PIMS | E1: % PIMS | F1: n infra | G1: % infra | H1: n coop | I1: % coop | J1: n mono | K1: % | L1: n multi | M1: % | N1: n personal | O1: n npersonal
A2: Data access mention | B2: =SUM(DISs!$B$2:$B$98) -> 13 | C2: =B2/$B$7 -> 0.24074074 | D2: =SUMIF(DISs!$L$2:$L$495,"subject",DISs!$B$2:$B$495) -> 9 | E2: =D2/$B$17 -> 0.25714286 | F2: =SUMIF(DISs!$L$2:$L$495,"enabler",DISs!$B$2:$B$495) -> 4 | G2: =F2/$B$18 -> 0.21052632 | H2: =SUMIF(DISs!$L$2:$L$495,"cooperative",DISs!$B$2:$B$495) -> 0 | I2: =H2*100/$B$19 -> #DIV/0! | J2: =SUMIF(DISs!$N$2:$N$495,"mono",DISs!$B$2:$B$495) -> 7 | K2: =J2/B13 -> 0.38888889 | L2: =SUMIF(DISs!$N$2:$N$495,"multi",DISs!$B$2:$B$495) -> 6 | M2: =L2/B14 -> 0.16666667 | N2: =SUMIF(DISs!$O$2:$O$495,"personal",DISs!$B$2:$B$495) -> 5 | O2: =SUMIF(DISs!$O$2:$O$495,"non-personal",DISs!$B$2:$B$495) -> 3
A3: Dedicated data access | B3: =SUM(DISs!$C$2:$C$98) -> 5 | C3: =B3/$B$7 -> 0.092592593 | D3: =SUMIF(DISs!$L$2:$L$495,"subject",DISs!$C$2:$C$495) -> 4 | E3: =D3/$B$17 -> 0.11428571 | F3: =SUMIF(DISs!$L$2:$L$495,"enabler",DISs!$C$2:$C$495) -> 1 | G3: =F3/$B$18 -> 0.052631579 | H3: =SUMIF(DISs!$L$2:$L$495,"cooperative",DISs!$C$2:$C$495) -> 0 | I3: =H3*100/$B$19 -> #DIV/0! | J3: =SUMIF(DISs!$N$2:$N$495,"mono",DISs!$C$2:$C$495) -> 5 | K3: =J3/B13 -> 0.27777778 | L3: =SUMIF(DISs!$N$2:$N$495,"multi",DISs!$C$2:$C$495) -> 0 | M3: =L3/B14 -> 0 | N3: =SUMIF(DISs!$O$2:$O$495,"personal",DISs!$C$2:$C$495) -> 4 | O3: =SUMIF(DISs!$O$2:$O$495,"non-personal",DISs!$C$2:$C$495) -> 1
A4: Documented implementation in research project | B4: =SUM(DISs!$D$2:$D$98) -> 12 | C4: =B4/$B$7 -> 0.22222222 | D4: =SUMIF(DISs!$L$2:$L$495,"subject",DISs!$D$2:$D$495) -> 10 | E4: =D4/$B$17 -> 0.28571429 | F4: =SUMIF(DISs!$L$2:$L$495,"enabler",DISs!$D$2:$D$495) -> 2 | G4: =F4/$B$18 -> 0.10526316 | H4: =SUMIF(DISs!$L$2:$L$495,"cooperative",DISs!$D$2:$D$495) -> 0 | I4: =H4*100/$B$19 -> #DIV/0! | J4: =SUMIF(DISs!$N$2:$N$495,"mono",DISs!$D$2:$D$495) -> 7 | K4: =J4/B13 -> 0.38888889 | L4: =SUMIF(DISs!$N$2:$N$495,"multi",DISs!$D$2:$D$495) -> 5 | M4: =L4/B14 -> 0.13888889 | N4: =SUMIF(DISs!$O$2:$O$495,"personal",DISs!$D$2:$D$495) -> 6 | O4: =SUMIF(DISs!$O$2:$O$495,"non-personal",DISs!$D$2:$D$495) -> 2
A7: tot | B7: 54
A13: unspecialised | B13: =COUNTIF(DISs!$N$2:$N$495,"mono") -> 18
A14: specialised | B14: =COUNTIF(DISs!$N$2:$N$495,"multi") -> 36
A15: tot agriculture | B15: =COUNTIF(DISs!$N$2:$N$495,"agriculture") -> 0
A16: order: State - NGO - Firm
A17: subject-centred | B17: =COUNTIF(DISs!$L$2:$L$495,"subject") -> 35
A18: infrastructure | B18: =COUNTIF(DISs!$L$2:$L$495,"enabler") -> 19
A19: cooperative | B19: =COUNTIF(DISs!$L$2:$L$495,"cooperative") -> 0
A26: n features | B26: frequency
A27: 0 | B27: =COUNTIF(DISs!$E$2:$E$495,A27) -> 38 | C27: 0 features
A28: 1 | B28: =COUNTIF(DISs!$E$2:$E$495,A28) -> 7 | C28: 1 features
A29: 2 | B29: =COUNTIF(DISs!$E$2:$E$495,A29) -> 4 | C29: 2 features
A30: 3 | B30: =COUNTIF(DISs!$E$2:$E$495,A30) -> 5 | C30: 3 features
A31: 4 | B31: =COUNTIF(DISs!$E$2:$E$495,A31) -> 0 | C31: 4 features
A32: 5 | B32: =COUNTIF(DISs!$E$2:$E$495,A32) -> 0 | C32: 5 features

Sheet Figure 5
A1: Feature | B1: n | C1: % | D1: n PIMS | E1: % PIMS | F1: n infra | G1: % infra | H1: n coop | I1: % coop | J1: n mono | K1: % | L1: n multi | M1: % | N1: n personal | O1: n npersonal
A2: Data access mention | B2: =SUM(DISs!$B$2:$B$98) -> 13 | C2: =B2/$B$7 -> 0.24074074 | D2: =SUMIF(DISs!$L$2:$L$495,"subject",DISs!$B$2:$B$495) -> 9 | E2: =D2/$B$17 -> 0.25714286 | F2: =SUMIF(DISs!$L$2:$L$495,"enabler",DISs!$B$2:$B$495) -> 4 | G2: =F2/$B$18 -> 0.21052632 | H2: =SUMIF(DISs!$L$2:$L$495,"cooperative",DISs!$B$2:$B$495) -> 0 | I2: =H2*100/$B$19 -> #DIV/0! | J2: =SUMIF(DISs!$N$2:$N$495,"mono",DISs!$B$2:$B$495) -> 7 | K2: =J2/B13 -> 0.38888889 | L2: =SUMIF(DISs!$N$2:$N$495,"multi",DISs!$B$2:$B$495) -> 6 | M2: =L2/B14 -> 0.16666667 | N2: =SUMIF(DISs!$O$2:$O$495,"personal",DISs!$B$2:$B$495) -> 5 | O2: =SUMIF(DISs!$O$2:$O$495,"non-personal",DISs!$B$2:$B$495) -> 3
A3: Dedicated data access | B3: =SUM(DISs!$C$2:$C$98) -> 5 | C3: =B3/$B$7 -> 0.092592593 | D3: =SUMIF(DISs!$L$2:$L$495,"subject",DISs!$C$2:$C$495) -> 4 | E3: =D3/$B$17 -> 0.11428571 | F3: =SUMIF(DISs!$L$2:$L$495,"enabler",DISs!$C$2:$C$495) -> 1 | G3: =F3/$B$18 -> 0.052631579 | H3: =SUMIF(DISs!$L$2:$L$495,"cooperative",DISs!$C$2:$C$495) -> 0 | I3: =H3*100/$B$19 -> #DIV/0! | J3: =SUMIF(DISs!$N$2:$N$495,"mono",DISs!$C$2:$C$495) -> 5 | K3: =J3/B13 -> 0.27777778 | L3: =SUMIF(DISs!$N$2:$N$495,"multi",DISs!$C$2:$C$495) -> 0 | M3: =L3/B14 -> 0 | N3: =SUMIF(DISs!$O$2:$O$495,"personal",DISs!$C$2:$C$495) -> 4 | O3: =SUMIF(DISs!$O$2:$O$495,"non-personal",DISs!$C$2:$C$495) -> 1
A4: Documented implementation in research project | B4: =SUM(DISs!$D$2:$D$98) -> 12 | C4: =B4/$B$7 -> 0.22222222 | D4: =SUMIF(DISs!$L$2:$L$495,"subject",DISs!$D$2:$D$495) -> 10 | E4: =D4/$B$17 -> 0.28571429 | F4: =SUMIF(DISs!$L$2:$L$495,"enabler",DISs!$D$2:$D$495) -> 2 | G4: =F4/$B$18 -> 0.10526316 | H4: =SUMIF(DISs!$L$2:$L$495,"cooperative",DISs!$D$2:$D$495) -> 0 | I4: =H4*100/$B$19 -> #DIV/0! | J4: =SUMIF(DISs!$N$2:$N$495,"mono",DISs!$D$2:$D$495) -> 7 | K4: =J4/B13 -> 0.38888889 | L4: =SUMIF(DISs!$N$2:$N$495,"multi",DISs!$D$2:$D$495) -> 5 | M4: =L4/B14 -> 0.13888889 | N4: =SUMIF(DISs!$O$2:$O$495,"personal",DISs!$D$2:$D$495) -> 6 | O4: =SUMIF(DISs!$O$2:$O$495,"non-personal",DISs!$D$2:$D$495) -> 2
A7: tot | B7: 54
A13: unspecialised | B13: =COUNTIF(DISs!$N$2:$N$495,"mono") -> 18
A14: specialised | B14: =COUNTIF(DISs!$N$2:$N$495,"multi") -> 36
A15: tot agriculture | B15: =COUNTIF(DISs!$N$2:$N$495,"agriculture") -> 0
A16: order: State - NGO - Firm
A17: subject-centred | B17: =COUNTIF(DISs!$L$2:$L$495,"subject") -> 35
A18: infrastructure | B18: =COUNTIF(DISs!$L$2:$L$495,"enabler") -> 19
A19: cooperative | B19: =COUNTIF(DISs!$L$2:$L$495,"cooperative") -> 0
A26: n features | B26: frequency
A27: 0 | B27: =COUNTIF(DISs!$E$2:$E$495,A27) -> 38 | C27: 0 features
A28: 1 | B28: =COUNTIF(DISs!$E$2:$E$495,A28) -> 7 | C28: 1 features
A29: 2 | B29: =COUNTIF(DISs!$E$2:$E$495,A29) -> 4 | C29: 2 features
A30: 3 | B30: =COUNTIF(DISs!$E$2:$E$495,A30) -> 5 | C30: 3 features
A31: 4 | B31: =COUNTIF(DISs!$E$2:$E$495,A31) -> 0 | C31: 4 features
A32: 5 | B32: =COUNTIF(DISs!$E$2:$E$495,A32) -> 0 | C32: 5 features

Sheet Figures_all
A1: Feature | B1: n | C1: % | D1: n PIMS | E1: % PIMS | F1: n infra | G1: % infra | H1: n coop | I1: % coop | J1: n mono | K1: % | L1: n multi | M1: % | N1: n personal | O1: n npersonal
A2: Data access mention | B2: =SUM(DISs!$B$2:$B$98) -> 13 | C2: =B2/$B$7 -> 0.24074074 | D2: =SUMIF(DISs!$L$2:$L$495,"subject",DISs!$B$2:$B$495) -> 9 | E2: =D2/$B$17 -> 0.25714286 | F2: =SUMIF(DISs!$L$2:$L$495,"enabler",DISs!$B$2:$B$495) -> 4 | G2: =F2/$B$18 -> 0.21052632 | H2: =SUMIF(DISs!$L$2:$L$495,"cooperative",DISs!$B$2:$B$495) -> 0 | I2: =H2*100/$B$19 -> #DIV/0! | J2: =SUMIF(DISs!$N$2:$N$495,"mono",DISs!$B$2:$B$495) -> 7 | K2: =J2/B13 -> 0.38888889 | L2: =SUMIF(DISs!$N$2:$N$495,"multi",DISs!$B$2:$B$495) -> 6 | M2: =L2/B14 -> 0.16666667 | N2: =SUMIF(DISs!$O$2:$O$495,"personal",DISs!$B$2:$B$495) -> 5 | O2: =SUMIF(DISs!$O$2:$O$495,"non-personal",DISs!$B$2:$B$495) -> 3
A3: Dedicated data access | B3: =SUM(DISs!$C$2:$C$98) -> 5 | C3: =B3/$B$7 -> 0.092592593 | D3: =SUMIF(DISs!$L$2:$L$495,"subject",DISs!$C$2:$C$495) -> 4 | E3: =D3/$B$17 -> 0.11428571 | F3: =SUMIF(DISs!$L$2:$L$495,"enabler",DISs!$C$2:$C$495) -> 1 | G3: =F3/$B$18 -> 0.052631579 | H3: =SUMIF(DISs!$L$2:$L$495,"cooperative",DISs!$C$2:$C$495) -> 0 | I3: =H3*100/$B$19 -> #DIV/0! | J3: =SUMIF(DISs!$N$2:$N$495,"mono",DISs!$C$2:$C$495) -> 5 | K3: =J3/B13 -> 0.27777778 | L3: =SUMIF(DISs!$N$2:$N$495,"multi",DISs!$C$2:$C$495) -> 0 | M3: =L3/B14 -> 0 | N3: =SUMIF(DISs!$O$2:$O$495,"personal",DISs!$C$2:$C$495) -> 4 | O3: =SUMIF(DISs!$O$2:$O$495,"non-personal",DISs!$C$2:$C$495) -> 1
A4: Documented implementation in research project | B4: =SUM(DISs!$D$2:$D$98) -> 12 | C4: =B4/$B$7 -> 0.22222222 | D4: =SUMIF(DISs!$L$2:$L$495,"subject",DISs!$D$2:$D$495) -> 10 | E4: =D4/$B$17 -> 0.28571429 | F4: =SUMIF(DISs!$L$2:$L$495,"enabler",DISs!$D$2:$D$495) -> 2 | G4: =F4/$B$18 -> 0.10526316 | H4: =SUMIF(DISs!$L$2:$L$495,"cooperative",DISs!$D$2:$D$495) -> 0 | I4: =H4*100/$B$19 -> #DIV/0! | J4: =SUMIF(DISs!$N$2:$N$495,"mono",DISs!$D$2:$D$495) -> 7 | K4: =J4/B13 -> 0.38888889 | L4: =SUMIF(DISs!$N$2:$N$495,"multi",DISs!$D$2:$D$495) -> 5 | M4: =L4/B14 -> 0.13888889 | N4: =SUMIF(DISs!$O$2:$O$495,"personal",DISs!$D$2:$D$495) -> 6 | O4: =SUMIF(DISs!$O$2:$O$495,"non-personal",DISs!$D$2:$D$495) -> 2
A7: tot | B7: 54
A13: unspecialised | B13: =COUNTIF(DISs!$N$2:$N$495,"mono") -> 18
A14: specialised | B14: =COUNTIF(DISs!$N$2:$N$495,"multi") -> 36
A15: tot agriculture | B15: =COUNTIF(DISs!$N$2:$N$495,"agriculture") -> 0
A16: order: State - NGO - Firm
A17: subject-centred | B17: =COUNTIF(DISs!$L$2:$L$495,"subject") -> 35
A18: infrastructure | B18: =COUNTIF(DISs!$L$2:$L$495,"enabler") -> 19
A19: cooperative | B19: =COUNTIF(DISs!$L$2:$L$495,"cooperative") -> 0
A26: n features | B26: frequency
A27: 0 | B27: =COUNTIF(DISs!$E$2:$E$495,A27) -> 38 | C27: 0 features
A28: 1 | B28: =COUNTIF(DISs!$E$2:$E$495,A28) -> 7 | C28: 1 features
A29: 2 | B29: =COUNTIF(DISs!$E$2:$E$495,A29) -> 4 | C29: 2 features
A30: 3 | B30: =COUNTIF(DISs!$E$2:$E$495,A30) -> 5 | C30: 3 features
A31: 4 | B31: =COUNTIF(DISs!$E$2:$E$495,A31) -> 0 | C31: 4 features
A32: 5 | B32: =COUNTIF(DISs!$E$2:$E$495,A32) -> 0 | C32: 5 features

Sheet DISs
A1: name | B1: Data access Mention | C1: Dedicated access researchers | D1: Documented access for research purposes | E1: sum | F1: country | G1: scope | H1: year_b | I1: year_e | J1: promoter | K1: governance | L1: type_1 | M1: type_2 | N1: data | O1: personal | P1: link_1 | Q1: link_2 | R1: link_3
A2: Bitsaboutme | B2: 1 | C2: 0 | D2: 1 | E2: =SUM(B2:D2) -> 2 | F2: #VALUE! | G2: Regional | H2: 2017 | I2: - | J2: Firm | K2: Firm | L2: subject | N2: multi | P2: https://bitsabout.me/en/contribute-to-the-research-on-the-impact-of-sars-cov-2/ | Q2: https://bitsabout.me/en/shop-smart-and-live-healthy-with-the-new-nutri-score/
A3: CGM LIFE | B3: 0 | C3: 0 | D3: 0 | E3: =SUM(B3:D3) -> 0 | F3: #VALUE! | G3: National | H3: 2021 | I3: 2023 | J3: Firm | K3: Firm | L3: subject | N3: mono | O3: personal | P3: https://cgmlife.nl/
A4: CitizenMe | B4: 1 | C4: 0 | D4: 1 | E4: =SUM(B4:D4) -> 2 | F4: #VALUE! | G4: Global | H4: 2014 | I4: - | J4: Firm | K4: Firm | L4: subject | M4: enabler | N4: multi | P4: https://www.citizenme.com/case-studies/gambling-and-the-fifa-world-cup-2022-part-1/
A5: City Data Exchange | B5: 0 | C5: 0 | D5: 0 | E5: =SUM(B5:D5) -> 0 | F5: #VALUE! | H5: 2015 | I5: 2018 | L5: enabler | N5: multi | P5: https://cphsolutionslab.dk/en/projekter/data-platforms/city-data-exchange
A6: clture | B6: 0 | C6: 0 | D6: 0 | E6: =SUM(B6:D6) -> 0 | F6: #VALUE! | G6: Global | K6: Firm | L6: subject | N6: multi | P6: https://www.clture.io/faq
A7: Cozy | B7: 0 | C7: 0 | D7: 0 | E7: =SUM(B7:D7) -> 0 | F7: #VALUE! | G7: Global | H7: 2017 | I7: - | J7: Firm | K7: Firm | L7: subject | N7: multi | P7: https://cozy.io/fr/
A8: Datafund | B8: 0 | C8: 0 | D8: 0 | E8: =SUM(B8:D8) -> 0 | F8: #VALUE! | G8: Global | H8: 2018 | I8: - | J8: Firm | K8: Firm | L8: subject | M8: enabler | N8: multi | P8: https://datafund.io/papers/Datafund_Business_Primer_Final_v09.pdf
A9: Dawex | B9: 1 | C9: 0 | D9: 1 | E9: =SUM(B9:D9) -> 2 | F9: #VALUE! | K9: Firm | L9: enabler | N9: multi | O9: non-personal | P9: https://www.dawex.com/en/ | Q9: https://www.dawex.com/en/services/consortiums/
A10: Digi.me | B10: 0 | C10: 0 | D10: 0 | E10: =SUM(B10:D10) -> 0 | F10: #VALUE! | G10: Global | H10: 2009 | I10: - | J10: Firm | K10: Firm | L10: subject | M10: enabler | N10: multi | P10: https://digi.me/partner-terms/ | Q10: https://digi.me/features-core
A11: DJustConnect | B11: 0 | C11: 0 | D11: 0 | E11: =SUM(B11:D11) -> 0 | F11: #VALUE! | L11: enabler | N11: mono | O11: non-personal | P11: https://djustconnect.be/en/getting-started
A12: Drimpy | B12: 0 | C12: 0 | D12: 1 | E12: =SUM(B12:D12) -> 1 | F12: #VALUE! | G12: National | H12: 2011 | I12: - | J12: Firm | K12: Firm | L12: subject | N12: mono | O12: personal | P12: https://www.drimpy.com/projecten/ | Q12: https://www.drimpy.com/projecten/mydigitwin/
A13: Fair Data Society | B13: 0 | C13: 0 | D13: 0 | E13: =SUM(B13:D13) -> 0 | F13: #VALUE! | G13: Global | H13: 2019 | I13: - | J13: NGO | K13: NGO | L13: enabler | N13: multi | P13: https://fairdatasociety.org/
A14: Gezondheidsmeter | B14: 1 | C14: 1 | D14: 1 | E14: =SUM(B14:D14) -> 3 | F14: #VALUE! | G14: National | H14: 2015 | I14: - | J14: Firm | K14: Firm | L14: subject | N14: mono | O14: personal | P14: https://www.gezondheidsmeter.nl/site/voor-zorgverleners | Q14: https://www.gezondheidsmeter.nl/site/modules/xcenter/?storyid=32
A15: HAT | B15: 0 | C15: 0 | D15: 0 | E15: =SUM(B15:D15) -> 0 | F15: #VALUE! | G15: Global | H15: 2012 | I15: - | J15: Firm | K15: Firm | L15: enabler | N15: multi | P15: https://www.hubofallthings.com/the-hat-ecosystem | Q15: https://www.hatcommunity.org/resources
A16: iDataSwift | B16: 1 | C16: 0 | D16: 0 | E16: =SUM(B16:D16) -> 1 | F16: #VALUE! | G16: Global | H16: 2012 | I16: - | J16: Firm | K16: Firm | L16: subject | M16: enabler | N16: multi | P16: https://www.dataswift.io/legal/legal | Q16: https://opencommons.org/Dataswift
A17: iGrant | B17: 0 | C17: 0 | D17: 0 | E17: =SUM(B17:D17) -> 0 | F17: #VALUE! | G17: Global | H17: 2017 | I17: - | J17: Firm | K17: Firm | L17: subject | M17: enabler | N17: multi | P17: https://docs.igrant.io/docs/ | Q17: https://igrant.io/
A18: ishare | B18: 0 | C18: 0 | D18: 0 | E18: =SUM(B18:D18) -> 0 | F18: #VALUE! | K18: NGO | L18: enabler | N18: multi | P18: https://ishare.eu/about-ishare/benefits/for-data-owners/
A19: Ivido | B19: 0 | C19: 0 | D19: 1 | E19: =SUM(B19:D19) -> 1 | F19: #VALUE! | G19: National | H19: 2014 | I19: - | J19: Firm | K19: Firm | L19: subject | N19: mono | O19: personal | P19: https://ivido.nl/ | Q19: https://ivido.nl/applicaties-voor-je-gezondheid/
A20: JoinData | B20: 1 | C20: 0 | D20: 0 | E20: =SUM(B20:D20) -> 1 | F20: #VALUE! | H20: 2017 | K20: Firm | L20: enabler | N20: mono | O20: non-personal | P20: https://join-data.nl/en/experience-stories/how-does-frieslandcampina-project-leader-laurens-guelen-experience-joindata/ | Q20: https://join-data.nl/organisatie/
A21: Lotame | B21: 0 | C21: 0 | D21: 0 | E21: =SUM(B21:D21) -> 0 | F21: #VALUE! | K21: Firm | L21: enabler | N21: multi | P21: https://www.lotame.com/pdx/marketplace/
A22: Luna | B22: 1 | C22: 1 | D22: 1 | E22: =SUM(B22:D22) -> 3 | F22: #VALUE! | K22: Firm | L22: subject | N22: mono | O22: personal | P22: https://www.lunadna.com/individuals/
A23: Marketplace.city | B23: 0 | C23: 0 | D23: 0 | E23: =SUM(B23:D23) -> 0 | F23: #VALUE! | L23: enabler | N23: multi | O23: non-personal | P23: https://marketplace.city/news/
A24: Medsafe | B24: 0 | C24: 0 | D24: 0 | E24: =SUM(B24:D24) -> 0 | F24: #VALUE! | G24: National | H24: 2022 | I24: - | J24: Firm | K24: Firm | L24: subject | N24: mono | O24: personal | P24: https://mijn.medsafe.io/auth
A25: medxpert | B25: 0 | C25: 0 | D25: 0 | E25: =SUM(B25:D25) -> 0 | F25: #VALUE! | G25: National | H25: 2015 | I25: - | J25: Firm | K25: Firm | L25: subject | N25: mono | O25: personal | P25: https://www.medxpert.app/
A26: Meeco | B26: 0 | C26: 0 | D26: 0 | E26: =SUM(B26:D26) -> 0 | F26: #VALUE! | G26: Global | H26: 2012 | I26: - | J26: Firm | K26: Firm | L26: enabler | M26: subject | N26: multi | P26: https://www.meeco.me/meeco-whitepaper | Q26: https://www.meeco.me/
A27: MIJNPGO | B27: 0 | C27: 0 | D27: 0 | E27: =SUM(B27:D27) -> 0 | F27: #VALUE! | G27: National | H27: 2019 | I27: - | J27: Firm | K27: Firm | L27: subject | N27: mono | O27: personal | P27: https://mijnpgo.org/
A28: MyDataMood | B28: 0 | C28: 0 | D28: 0 | E28: =SUM(B28:D28) -> 0 | F28: #VALUE! | G28: Global | H28: 2019 | I28: - | J28: Firm | K28: Firm | L28: subject | N28: multi | P28: https://mydatamood.com
A29: Mydex | B29: 0 | C29: 0 | D29: 0 | E29: =SUM(B29:D29) -> 0 | F29: #VALUE! | G29: Global | H29: 2007 | I29: - | J29: Firm | K29: Firm | L29: enabler | M29: subject | N29: multi | P29: https://mydex.org/platform-services/#inclued
A30: Myfairdata | B30: 0 | C30: 0 | D30: 0 | E30: =SUM(B30:D30) -> 0 | F30: #VALUE! | G30: Global | H30: 2020 | I30: - | J30: Firm | K30: Firm | L30: subject | N30: multi | P30: https://myfairdata.com/
A31: Ockto | B31: 0 | C31: 0 | D31: 0 | E31: =SUM(B31:D31) -> 0 | F31: #VALUE! | G31: National | H31: 2017 | I31: - | J31: Firm | K31: Firm | L31: subject | N31: multi | O31: personal | P31: https://ockto.eu/faq
A32: OneCub | B32: 1 | C32: 0 | D32: 0 | E32: =SUM(B32:D32) -> 1 | F32: #VALUE! | G32: Global | H32: 2011 | I32: - | J32: Firm | K32: Firm | L32: enabler | M32: subject | N32: multi | P32: https://www.onecub.com/solution/
A33: Ozone.ai | B33: 0 | C33: 0 | D33: 0 | E33: =SUM(B33:D33) -> 0 | F33: #VALUE! | K33: Firm | L33: subject | N33: multi | P33: https://web.archive.org/web/20201007100812/https://www.ozone.ai/
A34: Patients Know Best | B34: 1 | C34: 1 | D34: 1 | E34: =SUM(B34:D34) -> 3 | F34: #VALUE! | G34: Regional | H34: 2008 | I34: - | J34: Firm | K34: Firm | L34: subject | N34: mono | O34: personal | P34: https://patientsknowbest.com/about/ | Q34: https://patientsknowbest.com/commissioners/
A35: Personium | B35: 0 | C35: 0 | D35: 1 | E35: =SUM(B35:D35) -> 1 | F35: #VALUE! | G35: Regional | H35: 2008 | I35: - | J35: Firm | K35: Firm | L35: subject | N35: multi | P35: https://personium.io
A36: PolyPoly | B36: 0 | C36: 0 | D36: 0 | E36: =SUM(B36:D36) -> 0 | F36: #VALUE! | G36: Regional | H36: 2019 | I36: - | J36: Firm | K36: Firm | L36: subject | N36: multi | P36: https://polypoly-citizens.eu
A37: Prifina | B37: 0 | C37: 0 | D37: 0 | E37: =SUM(B37:D37) -> 0 | F37: #VALUE! | G37: Global | H37: 2017 | I37: - | J37: Firm | K37: Firm | L37: subject | N37: multi | O37: personal | P37: https://www.prifina.com/core-concept.html
A38: Qii | B38: 0 | C38: 0 | D38: 0 | E38: =SUM(B38:D38) -> 0 | F38: #VALUE! | G38: National | H38: 2015 | I38: - | J38: Firm | K38: Firm | L38: subject | N38: multi | P38: https://www.qii.nl/over-ons
A39: QIY | B39: 0 | C39: 0 | D39: 0 | E39: =SUM(B39:D39) -> 0 | F39: #VALUE! | G39: Global | H39: 2007 | I39: - | J39: NGO | K39: NGO-Firm | L39: enabler | M39: subject | N39: multi | P39: https://www.qiyfoundation.org/qiy-scheme/what-is-a-scheme/organisation/
A40: Quli | B40: 1 | C40: 0 | D40: 0 | E40: =SUM(B40:D40) -> 1 | F40: #VALUE! | G40: National | H40: 2013 | I40: - | J40: Firm | K40: Firm | L40: subject | M40: enabler | N40: mono | O40: personal | P40: https://www.quli.nl/quli-voor-patientgroepen/
...
